26/12/23 (14:43:46) | ERROR: <urlopen error timed out>
Traceback (most recent call last):
  File "/usr/lib/python3.11/urllib/request.py", line 1348, in do_open
    h.request(req.get_method(), req.selector, req.data, headers,
  File "/usr/lib/python3.11/http/client.py", line 1286, in request
    self._send_request(method, url, body, headers, encode_chunked)
  File "/usr/lib/python3.11/http/client.py", line 1332, in _send_request
    self.endheaders(body, encode_chunked=encode_chunked)
  File "/usr/lib/python3.11/http/client.py", line 1281, in endheaders
    self._send_output(message_body, encode_chunked=encode_chunked)
  File "/usr/lib/python3.11/http/client.py", line 1041, in _send_output
    self.send(msg)
  File "/usr/lib/python3.11/http/client.py", line 979, in send
    self.connect()
  File "/usr/lib/python3.11/http/client.py", line 1451, in connect
    super().connect()
  File "/usr/lib/python3.11/http/client.py", line 945, in connect
    self.sock = self._create_connection(
                ^^^^^^^^^^^^^^^^^^^^^^^^
  File "/usr/lib/python3.11/socket.py", line 851, in create_connection
    raise exceptions[0]
  File "/usr/lib/python3.11/socket.py", line 836, in create_connection
    sock.connect(sa)
TimeoutError: timed out

During handling of the above exception, another exception occurred:

Traceback (most recent call last):
  File "/usr/bin/bpytop", line 5029, in _checker
    with urllib.request.urlopen("https://github.com/aristocratos/bpytop/raw/master/bpytop.py", timeout=5) as source: # type: ignore
         ^^^^^^^^^^^^^^^^^^^^^^^^^^^^^^^^^^^^^^^^^^^^^^^^^^^^^^^^^^^^^^^^^^^^^^^^^^^^^^^^^^^^^^^^^^^^^^^^
  File "/usr/lib/python3.11/urllib/request.py", line 216, in urlopen
    return opener.open(url, data, timeout)
           ^^^^^^^^^^^^^^^^^^^^^^^^^^^^^^^
  File "/usr/lib/python3.11/urllib/request.py", line 525, in open
    response = meth(req, response)
               ^^^^^^^^^^^^^^^^^^^
  File "/usr/lib/python3.11/urllib/request.py", line 634, in http_response
    response = self.parent.error(
               ^^^^^^^^^^^^^^^^^^
  File "/usr/lib/python3.11/urllib/request.py", line 557, in error
    result = self._call_chain(*args)
             ^^^^^^^^^^^^^^^^^^^^^^^
  File "/usr/lib/python3.11/urllib/request.py", line 496, in _call_chain
    result = func(*args)
             ^^^^^^^^^^^
  File "/usr/lib/python3.11/urllib/request.py", line 749, in http_error_302
    return self.parent.open(new, timeout=req.timeout)
           ^^^^^^^^^^^^^^^^^^^^^^^^^^^^^^^^^^^^^^^^^^
  File "/usr/lib/python3.11/urllib/request.py", line 519, in open
    response = self._open(req, data)
               ^^^^^^^^^^^^^^^^^^^^^
  File "/usr/lib/python3.11/urllib/request.py", line 536, in _open
    result = self._call_chain(self.handle_open, protocol, protocol +
             ^^^^^^^^^^^^^^^^^^^^^^^^^^^^^^^^^^^^^^^^^^^^^^^^^^^^^^^
  File "/usr/lib/python3.11/urllib/request.py", line 496, in _call_chain
    result = func(*args)
             ^^^^^^^^^^^
  File "/usr/lib/python3.11/urllib/request.py", line 1391, in https_open
    return self.do_open(http.client.HTTPSConnection, req,
           ^^^^^^^^^^^^^^^^^^^^^^^^^^^^^^^^^^^^^^^^^^^^^^
  File "/usr/lib/python3.11/urllib/request.py", line 1351, in do_open
    raise URLError(err)
urllib.error.URLError: <urlopen error timed out>
26/12/23 (14:50:36) | ERROR: <urlopen error [Errno -3] Temporary failure in name resolution>
Traceback (most recent call last):
  File "/usr/lib/python3.11/urllib/request.py", line 1348, in do_open
    h.request(req.get_method(), req.selector, req.data, headers,
  File "/usr/lib/python3.11/http/client.py", line 1286, in request
    self._send_request(method, url, body, headers, encode_chunked)
  File "/usr/lib/python3.11/http/client.py", line 1332, in _send_request
    self.endheaders(body, encode_chunked=encode_chunked)
  File "/usr/lib/python3.11/http/client.py", line 1281, in endheaders
    self._send_output(message_body, encode_chunked=encode_chunked)
  File "/usr/lib/python3.11/http/client.py", line 1041, in _send_output
    self.send(msg)
  File "/usr/lib/python3.11/http/client.py", line 979, in send
    self.connect()
  File "/usr/lib/python3.11/http/client.py", line 1451, in connect
    super().connect()
  File "/usr/lib/python3.11/http/client.py", line 945, in connect
    self.sock = self._create_connection(
                ^^^^^^^^^^^^^^^^^^^^^^^^
  File "/usr/lib/python3.11/socket.py", line 827, in create_connection
    for res in getaddrinfo(host, port, 0, SOCK_STREAM):
               ^^^^^^^^^^^^^^^^^^^^^^^^^^^^^^^^^^^^^^^
  File "/usr/lib/python3.11/socket.py", line 962, in getaddrinfo
    for res in _socket.getaddrinfo(host, port, family, type, proto, flags):
               ^^^^^^^^^^^^^^^^^^^^^^^^^^^^^^^^^^^^^^^^^^^^^^^^^^^^^^^^^^^
socket.gaierror: [Errno -3] Temporary failure in name resolution

During handling of the above exception, another exception occurred:

Traceback (most recent call last):
  File "/usr/bin/bpytop", line 5029, in _checker
    with urllib.request.urlopen("https://github.com/aristocratos/bpytop/raw/master/bpytop.py", timeout=5) as source: # type: ignore
         ^^^^^^^^^^^^^^^^^^^^^^^^^^^^^^^^^^^^^^^^^^^^^^^^^^^^^^^^^^^^^^^^^^^^^^^^^^^^^^^^^^^^^^^^^^^^^^^^
  File "/usr/lib/python3.11/urllib/request.py", line 216, in urlopen
    return opener.open(url, data, timeout)
           ^^^^^^^^^^^^^^^^^^^^^^^^^^^^^^^
  File "/usr/lib/python3.11/urllib/request.py", line 519, in open
    response = self._open(req, data)
               ^^^^^^^^^^^^^^^^^^^^^
  File "/usr/lib/python3.11/urllib/request.py", line 536, in _open
    result = self._call_chain(self.handle_open, protocol, protocol +
             ^^^^^^^^^^^^^^^^^^^^^^^^^^^^^^^^^^^^^^^^^^^^^^^^^^^^^^^
  File "/usr/lib/python3.11/urllib/request.py", line 496, in _call_chain
    result = func(*args)
             ^^^^^^^^^^^
  File "/usr/lib/python3.11/urllib/request.py", line 1391, in https_open
    return self.do_open(http.client.HTTPSConnection, req,
           ^^^^^^^^^^^^^^^^^^^^^^^^^^^^^^^^^^^^^^^^^^^^^^
  File "/usr/lib/python3.11/urllib/request.py", line 1351, in do_open
    raise URLError(err)
urllib.error.URLError: <urlopen error [Errno -3] Temporary failure in name resolution>
26/12/23 (17:58:55) | ERROR: <urlopen error [Errno -3] Temporary failure in name resolution>
Traceback (most recent call last):
  File "/usr/lib/python3.11/urllib/request.py", line 1348, in do_open
    h.request(req.get_method(), req.selector, req.data, headers,
  File "/usr/lib/python3.11/http/client.py", line 1286, in request
    self._send_request(method, url, body, headers, encode_chunked)
  File "/usr/lib/python3.11/http/client.py", line 1332, in _send_request
    self.endheaders(body, encode_chunked=encode_chunked)
  File "/usr/lib/python3.11/http/client.py", line 1281, in endheaders
    self._send_output(message_body, encode_chunked=encode_chunked)
  File "/usr/lib/python3.11/http/client.py", line 1041, in _send_output
    self.send(msg)
  File "/usr/lib/python3.11/http/client.py", line 979, in send
    self.connect()
  File "/usr/lib/python3.11/http/client.py", line 1451, in connect
    super().connect()
  File "/usr/lib/python3.11/http/client.py", line 945, in connect
    self.sock = self._create_connection(
                ^^^^^^^^^^^^^^^^^^^^^^^^
  File "/usr/lib/python3.11/socket.py", line 827, in create_connection
    for res in getaddrinfo(host, port, 0, SOCK_STREAM):
               ^^^^^^^^^^^^^^^^^^^^^^^^^^^^^^^^^^^^^^^
  File "/usr/lib/python3.11/socket.py", line 962, in getaddrinfo
    for res in _socket.getaddrinfo(host, port, family, type, proto, flags):
               ^^^^^^^^^^^^^^^^^^^^^^^^^^^^^^^^^^^^^^^^^^^^^^^^^^^^^^^^^^^
socket.gaierror: [Errno -3] Temporary failure in name resolution

During handling of the above exception, another exception occurred:

Traceback (most recent call last):
  File "/usr/bin/bpytop", line 5029, in _checker
    with urllib.request.urlopen("https://github.com/aristocratos/bpytop/raw/master/bpytop.py", timeout=5) as source: # type: ignore
         ^^^^^^^^^^^^^^^^^^^^^^^^^^^^^^^^^^^^^^^^^^^^^^^^^^^^^^^^^^^^^^^^^^^^^^^^^^^^^^^^^^^^^^^^^^^^^^^^
  File "/usr/lib/python3.11/urllib/request.py", line 216, in urlopen
    return opener.open(url, data, timeout)
           ^^^^^^^^^^^^^^^^^^^^^^^^^^^^^^^
  File "/usr/lib/python3.11/urllib/request.py", line 519, in open
    response = self._open(req, data)
               ^^^^^^^^^^^^^^^^^^^^^
  File "/usr/lib/python3.11/urllib/request.py", line 536, in _open
    result = self._call_chain(self.handle_open, protocol, protocol +
             ^^^^^^^^^^^^^^^^^^^^^^^^^^^^^^^^^^^^^^^^^^^^^^^^^^^^^^^
  File "/usr/lib/python3.11/urllib/request.py", line 496, in _call_chain
    result = func(*args)
             ^^^^^^^^^^^
  File "/usr/lib/python3.11/urllib/request.py", line 1391, in https_open
    return self.do_open(http.client.HTTPSConnection, req,
           ^^^^^^^^^^^^^^^^^^^^^^^^^^^^^^^^^^^^^^^^^^^^^^
  File "/usr/lib/python3.11/urllib/request.py", line 1351, in do_open
    raise URLError(err)
urllib.error.URLError: <urlopen error [Errno -3] Temporary failure in name resolution>
